<mujoco model="double_pendulum">

    <!-- experimental -->
    <option timestep="0.01" gravity="0 0 -9.81"/>

    <asset>
        <texture type="skybox" builtin="gradient" rgb1="0.6 0.7 0.9" rgb2="0.3 0.3 0.4" width="512" height="3072"/>
        <texture type="2d" name="groundplane" builtin="checker" mark="edge" rgb1="0.2 0.3 0.4" rgb2="0.1 0.2 0.3" markrgb="0.8 0.8 0.8" width="300" height="300"/>
        <material name="groundplane" texture="groundplane" texuniform="true" texrepeat="5 5" reflectance="0.2"/>
    </asset>

    <worldbody>
        <light name="global_light" directional="true" diffuse="1 1 1" specular="0.3 0.3 0.3" castshadow="false"/>
        <light name="fill_light_0" pos="-5 0 10" dir="0 0 -1" directional="false" diffuse="1 1 1" specular="0.2 0.2 0.2"/>
        <light name="fill_light_1" pos="0 0 10" dir="0 0 -1" directional="false" diffuse="1 1 1" specular="0.2 0.2 0.2"/>
        <light name="fill_light_2" pos="5 0 10" dir="0 0 -1" directional="false" diffuse="1 1 1" specular="0.2 0.2 0.2"/>

        <geom name="floor" pos="0 0 0" size="0 0 0.05" type="plane" material="groundplane"/>

        <camera name="fixed" pos="0 -6 2.2" xyaxes="1 0 0 0 0 1"/>

        <!-- First link -->
        <body name="first_link" pos="0 0 2.2">
            <!-- <joint name="hinge1" type="hinge" axis="0 1 0" pos="0 0 0" damping="0.1"/> -->
            <joint name="hinge1" type="hinge" axis="0 1 0" pos="0 0 0" damping="0.5"/>
            <geom name="rod1" type="capsule" fromto="0 0 0 0 0 -1" size="0.02" mass="1"/>
            <geom name="bob1" type="sphere" pos="0 0 -1" size="0.05" rgba="1 0 0 1" mass="0"/>

            <!-- Second link attached to the first -->
            <body name="second_link" pos="0 0 -1">
                <!-- <joint name="hinge2" type="hinge" axis="0 1 0" pos="0 0 0" damping="0.1"/> -->
                <joint name="hinge2" type="hinge" axis="0 1 0" pos="0 0 0" damping="0.5"/>
                <geom name="rod2" type="capsule" fromto="0 0 0 0 0 -1" size="0.02" mass="1"/>
                <geom name="bob2" type="sphere" pos="0 0 -1" size="0.05" rgba="0 0 1 1" mass="0"/>
            </body>
        </body>
    </worldbody>

    <actuator>
        <!-- Optional: torque actuator to drive the pendulum -->
        <!-- <motor joint="hinge1" ctrlrange="-1 1" gear="1"/> -->
        <!-- <motor joint="hinge1" ctrlrange="-1 1" gear="4"/> -->
        <motor joint="hinge1" ctrlrange="-1 1" gear="6"/>
        <!-- <motor joint="hinge1" ctrlrange="-1 1" gear="8"/> -->
    </actuator>
</mujoco>